PS C:\Users\Magan.Dhaniya-mkt> & C:/Python313/python.exe c:/Users/Magan.Dhaniya-mkt/Desktop/bot/test.py
Reading schema ...
Schema summary (truncated): dbo.BCK2_rttSalesFnlNew(custCode:char, mnthYear:char, repoCatg:char, sbPrdCod:char, idenNumb:numeric, perBalCF:numeric, statFlag:char, createId:varchar, createDt:smalldatetime, custSale:numeric, retlSale:numeric, crFrvdSl:numeric, tlyTotSl:numeric, tlyMapSl:numeric, tlUnMpSl:numeric, mergeCod:char, 
Building dataset and training model ...
Found 1541 tables. Generating synthetic training pairs ...
Tables processed: 100%|████████████████████████████████████████████████████████████████████████████████████████████████████████████████████████████████████████████████████████████████████████████████████████████████████████| 1541/1541 [7:01:27<00:00, 16.41s/it]
Training pairs: train=392955, val=46230, test=23115
Loading base model from: t5-small
tokenizer_config.json: 100%|████████████████████████████████████████████████████████████████████████████████████████████████████████████████████████████████████████████████████████████████████████████████████████████████████| 2.32k/2.32k [00:00<00:00, 10.2MB/s]
C:\Users\Magan.Dhaniya-mkt\AppData\Roaming\Python\Python313\site-packages\huggingface_hub\file_download.py:143: UserWarning: `huggingface_hub` cache-system uses symlinks by default to efficiently store duplicated files but your machine does not support them in C:\Users\Magan.Dhaniya-mkt\.cache\huggingface\hub\models--t5-small. Caching files will still work but in a degraded version that might require more space on your disk. This warning can be disabled by setting the `HF_HUB_DISABLE_SYMLINKS_WARNING` environment variable. For more details, see https://huggingface.co/docs/huggingface_hub/how-to-cache#limitations.
To support symlinks on Windows, you either need to activate Developer Mode or to run Python as an administrator. In order to activate developer mode, see this article: https://docs.microsoft.com/en-us/windows/apps/get-started/enable-your-device-for-development  
  warnings.warn(message)
spiece.model: 100%|███████████████████████████████████████████████████████████████████████████████████████████████████████████████████████████████████████████████████████████████████████████████████████████████████████████████| 792k/792k [00:00<00:00, 2.96MB/s]
tokenizer.json: 100%|███████████████████████████████████████████████████████████████████████████████████████████████████████████████████████████████████████████████████████████████████████████████████████████████████████████| 1.39M/1.39M [00:00<00:00, 1.48MB/s]
You are using the default legacy behaviour of the <class 'transformers.models.t5.tokenization_t5.T5Tokenizer'>. This is expected, and simply means that the `legacy` (previous) behavior will be used so nothing changes for you. If you want to use the new behaviour, set `legacy=False`. This should only be set if you understand what it means, and thoroughly read the reason why this was added as explained in https://github.com/huggingface/transformers/pull/24565
config.json: 100%|██████████████████████████████████████████████████████████████████████████████████████████████████████████████████████████████████████████████████████████████████████████████████████████████████████████████| 1.21k/1.21k [00:00<00:00, 3.38MB/s]
Xet Storage is enabled for this repo, but the 'hf_xet' package is not installed. Falling back to regular HTTP download. For better performance, install the package with: `pip install huggingface_hub[hf_xet]` or `pip install hf_xet`
Traceback (most recent call last):
  File "C:\Users\Magan.Dhaniya-mkt\AppData\Roaming\Python\Python313\site-packages\urllib3\connectionpool.py", line 464, in _make_request
    self._validate_conn(conn)
    ~~~~~~~~~~~~~~~~~~~^^^^^^
  File "C:\Users\Magan.Dhaniya-mkt\AppData\Roaming\Python\Python313\site-packages\urllib3\connectionpool.py", line 1093, in _validate_conn
    conn.connect()
    ~~~~~~~~~~~~^^
  File "C:\Users\Magan.Dhaniya-mkt\AppData\Roaming\Python\Python313\site-packages\urllib3\connection.py", line 790, in connect
    sock_and_verified = _ssl_wrap_socket_and_match_hostname(
        sock=sock,
    ...<14 lines>...
        assert_fingerprint=self.assert_fingerprint,
    )
  File "C:\Users\Magan.Dhaniya-mkt\AppData\Roaming\Python\Python313\site-packages\urllib3\connection.py", line 969, in _ssl_wrap_socket_and_match_hostname
    ssl_sock = ssl_wrap_socket(
        sock=sock,
    ...<8 lines>...
        tls_in_tls=tls_in_tls,
    )
  File "C:\Users\Magan.Dhaniya-mkt\AppData\Roaming\Python\Python313\site-packages\urllib3\util\ssl_.py", line 480, in ssl_wrap_socket
    ssl_sock = _ssl_wrap_socket_impl(sock, context, tls_in_tls, server_hostname)
  File "C:\Users\Magan.Dhaniya-mkt\AppData\Roaming\Python\Python313\site-packages\urllib3\util\ssl_.py", line 524, in _ssl_wrap_socket_impl
    return ssl_context.wrap_socket(sock, server_hostname=server_hostname)
           ~~~~~~~~~~~~~~~~~~~~~~~^^^^^^^^^^^^^^^^^^^^^^^^^^^^^^^^^^^^^^^
  File "C:\Python313\Lib\ssl.py", line 455, in wrap_socket
    return self.sslsocket_class._create(
           ~~~~~~~~~~~~~~~~~~~~~~~~~~~~^
        sock=sock,
        ^^^^^^^^^^
    ...<5 lines>...
        session=session
        ^^^^^^^^^^^^^^^
    )
    ^
  File "C:\Python313\Lib\ssl.py", line 1076, in _create
    self.do_handshake()
    ~~~~~~~~~~~~~~~~~^^
  File "C:\Python313\Lib\ssl.py", line 1372, in do_handshake
    self._sslobj.do_handshake()
    ~~~~~~~~~~~~~~~~~~~~~~~~~^^
ssl.SSLCertVerificationError: [SSL: CERTIFICATE_VERIFY_FAILED] certificate verify failed: unable to get local issuer certificate (_ssl.c:1028)

During handling of the above exception, another exception occurred:

Traceback (most recent call last):
  File "C:\Users\Magan.Dhaniya-mkt\AppData\Roaming\Python\Python313\site-packages\urllib3\connectionpool.py", line 787, in urlopen
    response = self._make_request(
        conn,
    ...<10 lines>...
        **response_kw,
    )
  File "C:\Users\Magan.Dhaniya-mkt\AppData\Roaming\Python\Python313\site-packages\urllib3\connectionpool.py", line 488, in _make_request
    raise new_e
urllib3.exceptions.SSLError: [SSL: CERTIFICATE_VERIFY_FAILED] certificate verify failed: unable to get local issuer certificate (_ssl.c:1028)

The above exception was the direct cause of the following exception:

Traceback (most recent call last):
  File "C:\Users\Magan.Dhaniya-mkt\AppData\Roaming\Python\Python313\site-packages\requests\adapters.py", line 667, in send
    resp = conn.urlopen(
        method=request.method,
    ...<9 lines>...
        chunked=chunked,
    )
  File "C:\Users\Magan.Dhaniya-mkt\AppData\Roaming\Python\Python313\site-packages\urllib3\connectionpool.py", line 841, in urlopen
    retries = retries.increment(
        method, url, error=new_e, _pool=self, _stacktrace=sys.exc_info()[2]
    )
  File "C:\Users\Magan.Dhaniya-mkt\AppData\Roaming\Python\Python313\site-packages\urllib3\util\retry.py", line 519, in increment
    raise MaxRetryError(_pool, url, reason) from reason  # type: ignore[arg-type]
    ^^^^^^^^^^^^^^^^^^^^^^^^^^^^^^^^^^^^^^^^^^^^^^^^^^^
urllib3.exceptions.MaxRetryError: HTTPSConnectionPool(host='cas-bridge.xethub.hf.co', port=443): Max retries exceeded with url: /xet-bridge-us/621ffdc036468d709f174358/5b8bfc2f6adc7a5f097f02d2f09acc4572525485014bdf8f475fe1154bf7e838?X-Amz-Algorithm=AWS4-HMAC-SHA256&X-Amz-Content-Sha256=UNSIGNED-PAYLOAD&X-Amz-Credential=cas%2F20250820%2Fus-east-1%2Fs3%2Faws4_request&X-Amz-Date=20250820T152534Z&X-Amz-Expires=3600&X-Amz-Signature=c51944e562c7ee893fa924b5fac0ae327f6e6646b8cd03e45ac0e2ab2448e39a&X-Amz-SignedHeaders=host&X-Xet-Cas-Uid=public&response-content-disposition=inline%3B+filename*%3DUTF-8%27%27model.safetensors%3B+filename%3D%22model.safetensors%22%3B&x-id=GetObject&Expires=1755707134&Policy=eyJTdGF0ZW1lbnQiOlt7IkNvbmRpdGlvbiI6eyJEYXRlTGVzc1RoYW4iOnsiQVdTOkVwb2NoVGltZSI6MTc1NTcwNzEzNH19LCJSZXNvdXJjZSI6Imh0dHBzOi8vY2FzLWJyaWRnZS54ZXRodWIuaGYuY28veGV0LWJyaWRnZS11cy82MjFmZmRjMDM2NDY4ZDcwOWYxNzQzNTgvNWI4YmZjMmY2YWRjN2E1ZjA5N2YwMmQyZjA5YWNjNDU3MjUyNTQ4NTAxNGJkZjhmNDc1ZmUxMTU0YmY3ZTgzOCoifV19&Signature=vCpoLY8ky2AMWayusHE6S-wZTth~QywOV1TsedUAe-C27T6yyIMlCkwk0nXDY2ZyebIffgBKf1m6tQMXeoBTE32QyyonXDvFMYVqmfpa5QriGMaEXrONYcf7YFc5wqBK0O8Mt4eC0H01O-vQh5BdeirrlL4hUC~eFuaVqpq9lVCewDIG65WCM8IqbhfoPCFoSpu1CuEemODTDVQLH-YdG5OatmYMbfYDsxPMd~n7h6zpl4sv3FysY6CudNlqA41TpEidKdQyl08~M5emFfyXFbOO9iAgB02Ju9xS18J3GXnnUzZuTYaOGsnCkxky0UJrEv8Snr2PqD8FFYGKFsH7tg__&Key-Pair-Id=K2L8F4GPSG1IFC (Caused by SSLError(SSLCertVerificationError(1, '[SSL: CERTIFICATE_VERIFY_FAILED] certificate verify failed: unable to get local issuer certificate (_ssl.c:1028)')))

During handling of the above exception, another exception occurred:

Traceback (most recent call last):
  File "c:\Users\Magan.Dhaniya-mkt\Desktop\bot\test.py", line 304, in <module>
    main()
    ~~~~^^
  File "c:\Users\Magan.Dhaniya-mkt\Desktop\bot\test.py", line 265, in main
    tokenizer, model = get_tokenizer_and_model()
                       ~~~~~~~~~~~~~~~~~~~~~~~^^
  File "c:\Users\Magan.Dhaniya-mkt\Desktop\bot\test.py", line 190, in get_tokenizer_and_model
    model = T5ForConditionalGeneration.from_pretrained(model_id, local_files_only=bool(BASE_MODEL_PATH))
  File "C:\Users\Magan.Dhaniya-mkt\AppData\Roaming\Python\Python313\site-packages\transformers\modeling_utils.py", line 317, in _wrapper
    return func(*args, **kwargs)
  File "C:\Users\Magan.Dhaniya-mkt\AppData\Roaming\Python\Python313\site-packages\transformers\modeling_utils.py", line 4918, in from_pretrained
    checkpoint_files, sharded_metadata = _get_resolved_checkpoint_files(
                                         ~~~~~~~~~~~~~~~~~~~~~~~~~~~~~~^
        pretrained_model_name_or_path=pretrained_model_name_or_path,
        ^^^^^^^^^^^^^^^^^^^^^^^^^^^^^^^^^^^^^^^^^^^^^^^^^^^^^^^^^^^^
    ...<15 lines>...
        transformers_explicit_filename=transformers_explicit_filename,
        ^^^^^^^^^^^^^^^^^^^^^^^^^^^^^^^^^^^^^^^^^^^^^^^^^^^^^^^^^^^^^^
    )
    ^
  File "C:\Users\Magan.Dhaniya-mkt\AppData\Roaming\Python\Python313\site-packages\transformers\modeling_utils.py", line 1179, in _get_resolved_checkpoint_files
    resolved_archive_file = cached_file(pretrained_model_name_or_path, filename, **cached_file_kwargs)
  File "C:\Users\Magan.Dhaniya-mkt\AppData\Roaming\Python\Python313\site-packages\transformers\utils\hub.py", line 321, in cached_file
    file = cached_files(path_or_repo_id=path_or_repo_id, filenames=[filename], **kwargs)
  File "C:\Users\Magan.Dhaniya-mkt\AppData\Roaming\Python\Python313\site-packages\transformers\utils\hub.py", line 567, in cached_files
    raise e
  File "C:\Users\Magan.Dhaniya-mkt\AppData\Roaming\Python\Python313\site-packages\transformers\utils\hub.py", line 479, in cached_files
    hf_hub_download(
    ~~~~~~~~~~~~~~~^
        path_or_repo_id,
        ^^^^^^^^^^^^^^^^
    ...<10 lines>...
        local_files_only=local_files_only,
        ^^^^^^^^^^^^^^^^^^^^^^^^^^^^^^^^^^
    )
    ^
  File "C:\Users\Magan.Dhaniya-mkt\AppData\Roaming\Python\Python313\site-packages\huggingface_hub\utils\_validators.py", line 114, in _inner_fn
    return fn(*args, **kwargs)
  File "C:\Users\Magan.Dhaniya-mkt\AppData\Roaming\Python\Python313\site-packages\huggingface_hub\file_download.py", line 1010, in hf_hub_download
    return _hf_hub_download_to_cache_dir(
        # Destination
    ...<14 lines>...
        force_download=force_download,
    )
  File "C:\Users\Magan.Dhaniya-mkt\AppData\Roaming\Python\Python313\site-packages\huggingface_hub\file_download.py", line 1171, in _hf_hub_download_to_cache_dir
    _download_to_tmp_and_move(
    ~~~~~~~~~~~~~~~~~~~~~~~~~^
        incomplete_path=Path(blob_path + ".incomplete"),
        ^^^^^^^^^^^^^^^^^^^^^^^^^^^^^^^^^^^^^^^^^^^^^^^^
    ...<8 lines>...
        xet_file_data=xet_file_data,
        ^^^^^^^^^^^^^^^^^^^^^^^^^^^^
    )
    ^
  File "C:\Users\Magan.Dhaniya-mkt\AppData\Roaming\Python\Python313\site-packages\huggingface_hub\file_download.py", line 1738, in _download_to_tmp_and_move
    http_get(
    ~~~~~~~~^
        url_to_download,
        ^^^^^^^^^^^^^^^^
    ...<4 lines>...
        expected_size=expected_size,
        ^^^^^^^^^^^^^^^^^^^^^^^^^^^^
    )
    ^
  File "C:\Users\Magan.Dhaniya-mkt\AppData\Roaming\Python\Python313\site-packages\huggingface_hub\file_download.py", line 426, in http_get
    r = _request_wrapper(
        method="GET", url=url, stream=True, proxies=proxies, headers=headers, timeout=constants.HF_HUB_DOWNLOAD_TIMEOUT
    )
  File "C:\Users\Magan.Dhaniya-mkt\AppData\Roaming\Python\Python313\site-packages\huggingface_hub\file_download.py", line 309, in _request_wrapper
    response = http_backoff(method=method, url=url, **params, retry_on_exceptions=(), retry_on_status_codes=(429,))
  File "C:\Users\Magan.Dhaniya-mkt\AppData\Roaming\Python\Python313\site-packages\huggingface_hub\utils\_http.py", line 310, in http_backoff
    response = session.request(method=method, url=url, **kwargs)
  File "C:\Users\Magan.Dhaniya-mkt\AppData\Roaming\Python\Python313\site-packages\requests\sessions.py", line 589, in request
    resp = self.send(prep, **send_kwargs)
  File "C:\Users\Magan.Dhaniya-mkt\AppData\Roaming\Python\Python313\site-packages\requests\sessions.py", line 724, in send
    history = [resp for resp in gen]
                                ^^^
  File "C:\Users\Magan.Dhaniya-mkt\AppData\Roaming\Python\Python313\site-packages\requests\sessions.py", line 265, in resolve_redirects
    resp = self.send(
        req,
    ...<6 lines>...
        **adapter_kwargs,
    )
  File "C:\Users\Magan.Dhaniya-mkt\AppData\Roaming\Python\Python313\site-packages\requests\sessions.py", line 703, in send
    r = adapter.send(request, **kwargs)
  File "C:\Users\Magan.Dhaniya-mkt\AppData\Roaming\Python\Python313\site-packages\huggingface_hub\utils\_http.py", line 96, in send
    return super().send(request, *args, **kwargs)
           ~~~~~~~~~~~~^^^^^^^^^^^^^^^^^^^^^^^^^^
  File "C:\Users\Magan.Dhaniya-mkt\AppData\Roaming\Python\Python313\site-packages\requests\adapters.py", line 698, in send
    raise SSLError(e, request=request)
requests.exceptions.SSLError: (MaxRetryError("HTTPSConnectionPool(host='cas-bridge.xethub.hf.co', port=443): Max retries exceeded with url: /xet-bridge-us/621ffdc036468d709f174358/5b8bfc2f6adc7a5f097f02d2f09acc4572525485014bdf8f475fe1154bf7e838?X-Amz-Algorithm=AWS4-HMAC-SHA256&X-Amz-Content-Sha256=UNSIGNED-PAYLOAD&X-Amz-Credential=cas%2F20250820%2Fus-east-1%2Fs3%2Faws4_request&X-Amz-Date=20250820T152534Z&X-Amz-Expires=3600&X-Amz-Signature=c51944e562c7ee893fa924b5fac0ae327f6e6646b8cd03e45ac0e2ab2448e39a&X-Amz-SignedHeaders=host&X-Xet-Cas-Uid=public&response-content-disposition=inline%3B+filename*%3DUTF-8%27%27model.safetensors%3B+filename%3D%22model.safetensors%22%3B&x-id=GetObject&Expires=1755707134&Policy=eyJTdGF0ZW1lbnQiOlt7IkNvbmRpdGlvbiI6eyJEYXRlTGVzc1RoYW4iOnsiQVdTOkVwb2NoVGltZSI6MTc1NTcwNzEzNH19LCJSZXNvdXJjZSI6Imh0dHBzOi8vY2FzLWJyaWRnZS54ZXRodWIuaGYuY28veGV0LWJyaWRnZS11cy82MjFmZmRjMDM2NDY4ZDcwOWYxNzQzNTgvNWI4YmZjMmY2YWRjN2E1ZjA5N2YwMmQyZjA5YWNjNDU3MjUyNTQ4NTAxNGJkZjhmNDc1ZmUxMTU0YmY3ZTgzOCoifV19&Signature=vCpoLY8ky2AMWayusHE6S-wZTth~QywOV1TsedUAe-C27T6yyIMlCkwk0nXDY2ZyebIffgBKf1m6tQMXeoBTE32QyyonXDvFMYVqmfpa5QriGMaEXrONYcf7YFc5wqBK0O8Mt4eC0H01O-vQh5BdeirrlL4hUC~eFuaVqpq9lVCewDIG65WCM8IqbhfoPCFoSpu1CuEemODTDVQLH-YdG5OatmYMbfYDsxPMd~n7h6zpl4sv3FysY6CudNlqA41TpEidKdQyl08~M5emFfyXFbOO9iAgB02Ju9xS18J3GXnnUzZuTYaOGsnCkxky0UJrEv8Snr2PqD8FFYGKFsH7tg__&Key-Pair-Id=K2L8F4GPSG1IFC (Caused by SSLError(SSLCertVerificationError(1, '[SSL: CERTIFICATE_VERIFY_FAILED] certificate verify failed: unable to get local issuer certificate (_ssl.c:1028)')))"), '(Request ID: 92d49fab-fe4c-4ead-927b-3784edf6bc92)')
